Workbook
Name Average: 'Velocity Tracking'!$B$17

Sheet Project Data
A1: Project Name | B1: Robot Visual Perception
A3: Online team meeting | B3: https://fau.zoom-x.de/j/62836031488
A5: Production system (if any) | B5: Service Provided (later in the Project)
A6: Test system (if any) | B6: Local Webcam
A8: GitHub repository | B8: https://github.com/amosproj/amos2025ws04-robot-visual-perception
A9: GitHub feature board | B9: https://github.com/orgs/amosproj/projects/92
A10: GitHub imp-squared backlog | B10: https://github.com/orgs/amosproj/projects/95
A12: Team T-shirt (white) | B12: https://www.shirtinator.de/s/E_eIf-ElT4iidRVnqM8J5w
A13: Team T-shirt (black) | B13: https://www.shirtinator.de/s/R0CANDdWTRCOvCohq_encA
A15: Additional materials | B15: https://discord.gg/VDqD2Zfb
A17: Team maling list | B17: oss-amos-proj4@lists.fau.de
B19: https://happy-amos.appspot.com/
B20: Please use our mailing list for written communication. Only CC teachers (university) and coaches on specific topics, as the mailing lists are very long.

Sheet Project Team
A1: Last Name | B1: First Name | C1: GitHub User Name | D1: Email Address
A2: Hilgers | B2: Felix | C2: fhilgers | D2: felix.hilgers@fau.de
A3: Samdani | B3: Sarib | C3: saribx | D3: saribstudent@gmail.com
A4: Chinbat | B4: Anuun | C4: anuunchin | D4: anuun.ch@gmail.com
A5: Goldschmidt | B5: Georgina | C5: bu31punu | D5: dzsini.lost@gmail.com
A6: Zinn | B6: Benedikt | C6: BenediktZinn | D6: benedikt.wh.zinn@gmail.com
A7: Badura | B7: Emil | C7: Tenebrae311 | D7: badura@tu-berlin.de
A8: Assenbaum | B8: Paul | C8: Paul2607 | D8: paul.assenbaum@fau.de
A9: Mantsch | B9: Christoph | C9: Christoph-Mantsch | D9: christoph.cm.mantsch@fau.de
A10: Asadi | B10: Zohreh | C10: zohrehasadi00 | D10: z.asadi@campus.tu-berlin.de

Sheet Role Assignments
C1: Product Owner
A2: # | B2: Meeting Day | C2: Review | D2: Planning | E2: Software Developer | F2: Release Manager | G2: Scrum Master | H2: Comment
A3: 1 | B3: 45952 | C3: Felix Hilgers | D3: Benedikt Zinn | E3: Everyone else | F3: Paul Assenbaum | G3: Georgina Goldschmidt | H3: (Tuesday 21. Discord for Release process example)
A4: 2 | B4: =B3+7 -> 45959 | C4: Benedikt Zinn | D4: Felix Hilgers | E4: Everyone else | F4: Anuun Chinbat | G4: Georgina Goldschmidt
A5: 3 | B5: =B4+7 -> 45966 | C5: Benedikt Zinn | D5: Felix Hilgers | E5: Everyone else | F5: Sarib Samdani | G5: Georgina Goldschmidt
A6: 4 | B6: =B5+7 -> 45973 | C6: Felix Hilgers | D6: Benedikt Zinn | E6: Everyone else | F6: Sarib Samdani | G6: Georgina Goldschmidt
A7: 5 | B7: =B6+7 -> 45980 | C7: Felix Hilgers | D7: Benedikt Zinn | E7: Everyone else | F7: Anuun Chinbat | G7: Georgina Goldschmidt
A8: 6 | B8: =B7+7 -> 45987 | C8: Benedikt Zinn | D8: Felix Hilgers | E8: Everyone else | F8: Emil Badura | G8: Georgina Goldschmidt
A9: 7 | B9: =B8+7 -> 45994 | C9: Felix Hilgers | D9: Benedikt Zinn | E9: Everyone else | F9: Emil Badura | G9: Georgina Goldschmidt | H9: Mid-term due
A10: 8 | B10: =B9+7 -> 46001 | C10: Benedikt Zinn | D10: Felix Hilgers | E10: Everyone else | F10: Paul Assenbaum | G10: Georgina Goldschmidt
A11: 9 | B11: =B10+7 -> 46008 | C11: Felix Hilgers | D11: Benedikt Zinn | E11: Everyone else | F11: Christoph Mantsch | G11: Georgina Goldschmidt
A12: 10 | B12: 44937 | C12: Benedikt Zinn | D12: Felix Hilgers | E12: Everyone else | F12: Christoph Mantsch | G12: Georgina Goldschmidt
A13: 11 | B13: =B12+7 -> 44944 | C13: Felix Hilgers | D13: Benedikt Zinn | E13: Everyone else | F13: Zohreh Asadi | G13: Georgina Goldschmidt
A14: 12 | B14: =B13+7 -> 44951 | C14: Benedikt Zinn | D14: Felix Hilgers | E14: Everyone else | F14: Zohreh Asadi | G14: Georgina Goldschmidt
A15: 13 | B15: =B14+7 -> 44958 | C15: Felix Hilgers | D15: Benedikt Zinn | E15: Everyone else | G15: Georgina Goldschmidt
A16: 14 | B16: =B15+7 -> 44965 | C16: Benedikt Zinn | D16: Felix Hilgers | E16: Everyone else | G16: Georgina Goldschmidt | H16: Demo day!
A17: 15 | B17: =B16+7 -> 44972 | C17: Felix Hilgers | D17: Benedikt Zinn | E17: Everyone else | G17: Georgina Goldschmidt | H17: Retrospective
A19: Product owners, software developers, and Scurm Master are set and ideally don't change over time; the critical part is the Release Manager role you need to define here

Sheet Team Contract
A1: Goals | B1: Development of a visual perception system for robots with an accuracy of >= 90%
A3: Meeting norms | B3: Zoom-Meetings in the meeting room of the university. Joining the meeting is mandatory, with exceptions (like sickness, etc.). As an exception, showing up to 10 minutes late is fine if the team is informed via discord. Happiness Index: has to be completed at the end of the meeting (amos happy). Stand-up-mails: containing -> things done, problems encountered, things up next. -> For SDs: min 2x per week -> For POs: min 1x per week
A5: Working norms | B5: Issues on Github in the “Feature board” project of the repository. Definition of Done: If specified in the issue that the feature has to be tested, tests have to be written for that feature, documented (in code or later in the wiki) Git-branches: The latest commit on the main-branch has to be tagged. Only 2 “in progress” tickets per person at one time.
A7: Coordination norms | B7: Developers can create issues but not put them onto the “Feature board”. If blocked by a different task, discuss it as soon as possible. Communication should happen via Discord & mail. Criticism should be constructive. Language should be respectful at all times, both verbal and written communication.
A9: Communication norms | B9: Developers can create issues but not put them onto the “Feature board”. If blocked by a different task, discuss it as soon as possible. Communication should happen via Discord & mail. Criticism should be constructive. Language should be respectful at all times, both verbal and written communication.
A11: Consideration norms
A13: Cont. improvement norms
A15: Rewards | B15: Online coffee or lunch meet at some point.
A17: Sanctions | B17: Document absence. Repeated absence is addressed with the missing person directly but will later be escalated to professors.
A19: Signatures
A21: Scrum Master | B21: Georgina Goldschmidt
A22: Product owner | B22: Felix Hilgers
A23: Product owner | B23: Benedikt Zinn
A24: Software developer | B24: Sarib Samdani
A25: Software developer | B25: Emil Badura
A26: Software developer | B26: Anuun Chinbat
A27: Software developer | B27: Paul Assenbaum
A28: Software developer | B28: Christoph Mantsch
A29: Software developer | B29: Zohreh Asadi

Sheet Product Goal
A1: Product Vision | B1: Project Mission
A3: Optibot helps people when operating robots equipped with a single camera. It gives real-time distance estimates for known objects inside the field of view of said camera without relying on other sensors. The software stack is easy to integrate with already existing WebRTC based systems, making it easy to enhance existing robot networks. | B3: The mission of this project is to create a containerized system that processes a WebRTC stream as an input and outputs a stream of metadata. This metadata will contain the objects detected in a certain frame of the video stream, their bounding boxes in the image & the estimated distance. This information can be overlayed over the existing video stream in a React component. All components of the project have well definied interfaces and can easily be integrated into existing architectures.

Sheet Product Glossary
A1: Term | B1: Definition

Sheet Sprint Goals
A1: Sprint # | B1: Sprint goal
A2: 1 | B2: Meeting with industry partner and getting things started (and the T-shirt of course)
A3: =A2+1 -> 2 | B3: Start work on individual components and research unclear topics
A4: =A3+1 -> 3 | B4: Combining components into a first working prototype
A5: =A4+1 -> 4 | B5: Refining prototype and splitting out components
A6: =A5+1 -> 5 | B6: Finishing the Implementation of the Initial Architecture
A7: =A6+1 -> 6 | B7: Refine component parts
A8: =A7+1 -> 7 | B8: Improve Extensibility and Documentation
A9: =A8+1 -> 8
A10: =A9+1 -> 9
A11: =A10+1 -> 10
A12: =A11+1 -> 11
A13: =A12+1 -> 12
A14: =A13+1 -> 13
A15: =A14+1 -> 14
A16: =A15+1 -> 15

Sheet Velocity Tracking
A1: Sprint # | B1: Story Points Realized
A2: 1 | B2: 0
A3: =A2+1 -> 2 | B3: =SUM('Mid-Project Release plan'!B21:F24) -> 14
A4: =A3+1 -> 3 | B4: =SUM('Mid-Project Release plan'!B26:F32) -> 22
A5: =A4+1 -> 4 | B5: =SUM('Mid-Project Release plan'!B34:F36) -> 11
A6: =A5+1 -> 5 | B6: =SUM('Mid-Project Release plan'!B38:F45) -> 21
A7: =A6+1 -> 6
A8: =A7+1 -> 7
A9: =A8+1 -> 8
A10: =A9+1 -> 9
A11: =A10+1 -> 10
A12: =A11+1 -> 11
A13: =A12+1 -> 12
A14: =A13+1 -> 13
A15: =A14+1 -> 14
A16: =A15+1 -> 15

Sheet Velocity Chart
A1: Average
A2: =AVERAGE('Velocity Tracking'!B$2:B$16) -> 13.6
A3: =AVERAGE('Velocity Tracking'!B$2:B$16) -> 13.6
A4: =AVERAGE('Velocity Tracking'!B$2:B$16) -> 13.6
A5: =AVERAGE('Velocity Tracking'!B$2:B$16) -> 13.6
A6: =AVERAGE('Velocity Tracking'!B$2:B$16) -> 13.6
A7: =AVERAGE('Velocity Tracking'!B$2:B$16) -> 13.6
A8: =AVERAGE('Velocity Tracking'!B$2:B$16) -> 13.6
A9: =AVERAGE('Velocity Tracking'!B$2:B$16) -> 13.6
A10: =AVERAGE('Velocity Tracking'!B$2:B$16) -> 13.6
A11: =AVERAGE('Velocity Tracking'!B$2:B$16) -> 13.6
A12: =AVERAGE('Velocity Tracking'!B$2:B$16) -> 13.6
A13: =AVERAGE('Velocity Tracking'!B$2:B$16) -> 13.6
... A16: =AVERAGE('Velocity Tracking'!B$2:B$16) -> 13.6

Sheet Mid-Project Release plan
A1: Sprint | B1: Goal | C1: Feature Name | D1: Est. size | E1: Est. remaining | F1: Real size | G1: Real remaining
A3: Release
A5: Total | D5: =sum(D8:D16) -> 121 | E5: =D5 -> 121
A7: Sprints
E8: Estimated burn-down | G8: Real burn-down
A9: =ROW()-8 -> 1 | B9: ='Sprint Goals'!B2 -> Meeting with industry partner and getting things started (and the T-shirt of course) | D9: =sum(D19) -> 0 | E9: =$D$5 -> 121 | F9: =sum(F19) -> 0 | G9: =$D$5 -> 121
A10: =ROW()-8 -> 2 | B10: ='Sprint Goals'!B3 -> Start work on individual components and research unclear topics | D10: =sum(D20:D24) -> 16 | E10: =E9-D9 -> 121 | F10: =sum(F21:F24) -> 14 | G10: =G9-F9 -> 121
A11: =ROW()-8 -> 3 | B11: ='Sprint Goals'!B4 -> Combining components into a first working prototype | D11: =sum(D25:D32) -> 21 | E11: =E10-D10 -> 105 | F11: =sum(F25:F32) -> 22 | G11: =G10-F10 -> 107
A12: =ROW()-8 -> 4 | B12: ='Sprint Goals'!B5 -> Refining prototype and splitting out components | D12: =sum(D33:D36) -> 13 | E12: =E11-D11 -> 84 | F12: =sum(F33:F36) -> 11 | G12: =G11-F11 -> 85
A13: =ROW()-8 -> 5 | B13: ='Sprint Goals'!B6 -> Finishing the Implementation of the Initial Architecture | D13: =Sum(D37:D45) -> 25 | E13: =E12-D12 -> 71 | F13: =sum(F37:F45) -> 21 | G13: =G12-F12 -> 74
A14: =ROW()-8 -> 6 | B14: ='Sprint Goals'!B7 -> Refine component parts | D14: =Sum(D47:D61) -> 46 | E14: =E13-D13 -> 46 | F14: =Sum(F47:F61) -> 0 | G14: =G13-F13 -> 53
A17: Features
A19: =A9 -> 1 | B19: =B9 -> Meeting with industry partner and getting things started (and the T-shirt of course)
A20: =A10 -> 2 | B20: =B10 -> Start work on individual components and research unclear topics
C21: Setup Architecture | D21: 5 | F21: 5
C22: Serve Webcam as WebRTC stream | D22: 5 | F22: 5
C23: Setup Initial CI Pipeline | D23: 3 | F23: 3
C24: Discuss Team Distribution Preferences | D24: 3 | F24: 1
A25: =A11 -> 3 | B25: =B11 -> Combining components into a first working prototype
C26: Keep BOM up to date | D26: 2 | F26: 2
C27: Setup REUSE licensing | D27: 2 | F27: 3
C28: Update Architecture document | D28: 2 | F28: 2
C29: Create Object Detection Example | D29: 3 | F29: 3
C30: Prepare Build Process Review | D30: 2 | F30: 2
C31: Prepare Depth Estimation | D31: 5 | F31: 5
C32: Research Object and Depth Estimation | D32: 5 | F32: 5
A33: =A12 -> 4 | B33: =B12 -> Refining prototype and splitting out components
C34: Metadata Transport | D34: 5 | F34: 3
C35: Split Backend Responsibilities | D35: 3 | F35: 3
C36: Improve Code Quality | D36: 5 | F36: 5
A37: =A13 -> 5 | B37: =B13 -> Finishing the Implementation of the Initial Architecture
C38: Remove Redundant Calculations | D38: 3 | F38: 3
C39: Utilize Library for detecting Object dimensions | D39: 5 | F39: 5
C40: Create a React Video Component | D40: 3 | F40: 3
C41: Investigate and Fix startup TIme | D41: 5 | F41: 3
C42: Fix Windows Development setup | D42: 3 | F42: 3
C43: Create a React Video Overlay | D43: 3 | F43: 3
C44: Build Process Video | D44: 1 | F44: 1
C45: Update Container Images | D45: 2 | F45: 0
A47: =A14 -> 6 | B47: =B14 -> Refine component parts
...

Sheet Burndown Chart

Sheet Final Project Release plan
A1: Sprint | B1: Goal | C1: Feature Name | D1: Est. size | E1: Est. remaining | F1: Real size | G1: Real remaining
A3: Release
A5: Total | D5: =sum(D8:D13) -> 0 | E5: =D5 -> 0
A7: Sprints
E8: Estimated burn-down | G8: Real burn-down
A9: 1 | D9: =sum(D16:D21) -> 0 | E9: =$D$5 -> 0 | F9: =sum(F16:F21) -> 0 | G9: =$D$5 -> 0
A10: =A9+1 -> 2 | D10: =sum(D22:D27) -> 0 | E10: =E9-D9 -> 0 | F10: =sum(F22:F27) -> 0 | G10: =G9-F9 -> 0
A11: =A10+1 -> 3 | D11: =sum(D28:D33) -> 0 | E11: =E10-D10 -> 0 | F11: =sum(F28:F33) -> 0 | G11: =G10-F10 -> 0
A12: ... | E12: =E11-D11 -> 0 | G12: =G11-F11 -> 0
A14: Features
A16: =A9 -> 1
A22: =A10 -> 2
A28: =A11 -> 3
C33: PLEASE CREATE THE BURNDOWN CHART ON A NEW TAB USING THE DATA FROM THIS TAB

Sheet Definition of Done
A1: # | B1: Feature Definition of Done | C1: Sprint Release Definition of Done | D1: Project Release Definition of Done
B2: Code has been reviewed by at least one SD | C2: All Software Components are functioning | D2: Architecture documentation has been updated
B3: Feature has been reviewed by at least one PO | C3: Sprint release notes have been generated from all merge-requests since the last release | D3: Tests exist for all mayor features
B4: Build scripts have been adapted if necessary | C4: All container communication is working | D4: All tests are passing
B5: CI Pipeline Passes
B6: Code has been merged to main
B7: BOM has been updated if necessary

Sheet Documentation
A1: Type | B1: Link / reference

Sheet Bill of Materials
A1: # | B1: Context | C1: Name | D1: Version | E1: License | F1: Comment
A2: 1 | B2: Frontend (React UI) | C2: npm:react | D2: 18.3.1 | E2: MIT
A3: 2 | B3: Frontend (React UI) | C3: npm:react-dom | D3: 18.3.1 | E3: MIT
A4: 3 | B4: Backend (FastAPI API) | C4: pypi:aioice | D4: 0.10.1 | E4: BSD-3-Clause
A5: 4 | B5: Backend (FastAPI API) | C5: pypi:aiortc | D5: 1.14.0 | E5: BSD-3-Clause
A6: 5 | B6: Backend (FastAPI API) | C6: pypi:av | D6: 16.0.1 | E6: BSD-3-Clause
A7: 6 | B7: Backend (FastAPI API) | C7: pypi:fastapi | D7: 0.115.10 | E7: MIT
A8: 7 | B8: Backend (FastAPI API) | C8: pypi:httpx | D8: 0.27.2 | E8: BSD License
A9: 8 | B9: Backend (FastAPI API) | C9: pypi:numpy | D9: 1.26.4 | E9: BSD-3-Clause
A10: 9 | B10: Backend (FastAPI API) | C10: pypi:onnx | D10: 1.19.1 | E10: Apache License v2.0
A11: 10 | B11: Backend (FastAPI API) | C11: pypi:onnxruntime | D11: 1.20.1 | E11: MIT License
A12: 11 | B12: Backend (FastAPI API) | C12: pypi:onnxruntime-gpu | D12: 1.23.2 | E12: MIT License
A13: 12 | B13: Backend (FastAPI API) | C13: pypi:onnxscript | D13: 0.5.6 | E13: MIT
... A37: 36 | B37: Frontend (React UI) | C37: npm:vitest | D37: 2.1.5 | E37: MIT

Sheet Planning Poker
A1: ='Project Team'!A1 -> Last Name | B1: ='Project Team'!B1 -> First Name | C1: Value
A2: ='Project Team'!A2 -> Hilgers | B2: ='Project Team'!B2 -> Felix | E2: =average(C2:C8) -> #DIV/0! | F2: =if(stdev(C2:C6) > 0,"NOK", "OK") -> #DIV/0!
A4: ='Project Team'!A3 -> Samdani | B4: ='Project Team'!B3 -> Sarib
A5: ='Project Team'!A4 -> Chinbat | B5: ='Project Team'!B4 -> Anuun
A6: ='Project Team'!A7 -> Badura | B6: ='Project Team'!B7 -> Emil | E6: 0 | F6: No size
A7: ='Project Team'!A8 -> Assenbaum | B7: ='Project Team'!B8 -> Paul | E7: 1 | F7: Trivial size
A8: ='Project Team'!A9 -> Mantsch | B8: ='Project Team'!B9 -> Christoph | E8: 2 | F8: Small size
A9: Asadi | B9: Zohreh | E9: 3 | F9: Medium size
E10: 5 | F10: Large size
A11: ='Project Team'!A5 -> Goldschmidt | B11: ='Project Team'!B5 -> Georgina | E11: 8 | F11: Very large size
A12: ='Project Team'!A6 -> Zinn | B12: Benedikt | E12: 13 | F12: Too large (size)
A14: How to play planning poker
A16: 1. Everyone type their number into their value field, don't hit return yet
A17: 2. Someone, perhaps a product owner, count down 3.. 2.. 1..
A18: 3. Then, everyone hit return to submit their value
G19: no cap yet
