Workbook

Sheet Project Data
A1: Project Name | B1: Robot Visual Perception
A3: Online team meeting | B3: https://fau.zoom-x.de/j/62836031488
A5: Production system (if any) | B5: Service Provided (later in the Project)
A6: Test system (if any) | B6: Local Webcam
A8: GitHub repository | B8: https://github.com/amosproj/amos2025ws04-robot-visual-perception
A9: GitHub feature board | B9: https://github.com/orgs/amosproj/projects/92
A10: GitHub imp-squared backlog | B10: https://github.com/orgs/amosproj/projects/95
A12: Team T-shirt (white) | B12: https://www.shirtinator.de/s/E_eIf-ElT4iidRVnqM8J5w
A13: Team T-shirt (black) | B13: https://www.shirtinator.de/s/R0CANDdWTRCOvCohq_encA
A15: Additional materials | B15: https://discord.gg/VDqD2Zfb
A17: Team maling list | B17: oss-amos-proj4@lists.fau.de
B19: https://happy-amos.appspot.com/
B20: Please use our mailing list for written communication. Only CC teachers (university) and coaches on specific topics, as the mailing lists are very long.

Sheet Project Team
A1: Last Name | B1: First Name | C1: GitHub User Name | D1: Email Address
A2: Hilgers | B2: Felix | C2: fhilgers | D2: felix.hilgers@fau.de
A3: Samdani | B3: Sarib | C3: saribx | D3: saribstudent@gmail.com
A4: Chinbat | B4: Anuun | C4: anuunchin | D4: anuun.ch@gmail.com
A5: Goldschmidt | B5: Georgina | C5: bu31punu | D5: dzsini.lost@gmail.com
A6: Zinn | B6: Benedikt | C6: BenediktZinn | D6: benedikt.wh.zinn@gmail.com
A7: Badura | B7: Emil | C7: Tenebrae311 | D7: badura@tu-berlin.de
A8: Assenbaum | B8: Paul | C8: Paul2607 | D8: paul.assenbaum@fau.de
A9: Mantsch | B9: Christoph | C9: Christoph-Mantsch | D9: christoph.cm.mantsch@fau.de
A10: Asadi | B10: Zohreh | C10: zohrehasadi00 | D10: z.asadi@campus.tu-berlin.de

Sheet Role Assignments
C1: Product Owner
A2: # | B2: Meeting Day | C2: Review | D2: Planning | E2: Software Developer | F2: Release Manager | G2: Scrum Master | H2: Comment
A3: 1 | B3: 45952 | C3: Felix Hilgers | D3: Benedikt Zinn | E3: Everyone else | F3: Paul Assenbaum | G3: Georgina Goldschmidt | H3: (Tuesday 21. Discord for Release process example)
A4: 2 | B4: =B3+7 -> 45959 | C4: Benedikt Zinn | D4: Felix Hilgers | E4: Everyone else | F4: Anuun Chinbat | G4: Georgina Goldschmidt
A5: 3 | B5: =B4+7 -> 45966 | C5: Benedikt Zinn | D5: Felix Hilgers | E5: Everyone else | F5: Sarib Samdani | G5: Georgina Goldschmidt
A6: 4 | B6: =B5+7 -> 45973 | C6: Felix Hilgers | D6: Benedikt Zinn | E6: Everyone else | F6: Sarib Samdani | G6: Georgina Goldschmidt
A7: 5 | B7: =B6+7 -> 45980 | C7: Felix Hilgers | D7: Benedikt Zinn | E7: Everyone else | F7: Anuun Chinbat | G7: Georgina Goldschmidt
A8: 6 | B8: =B7+7 -> 45987 | C8: Benedikt Zinn | D8: Felix Hilgers | E8: Everyone else | F8: Emil Badura | G8: Georgina Goldschmidt
A9: 7 | B9: =B8+7 -> 45994 | C9: Felix Hilgers | D9: Benedikt Zinn | E9: Everyone else | F9: Emil Badura | G9: Georgina Goldschmidt | H9: Mid-term due
A10: 8 | B10: =B9+7 -> 46001 | C10: Benedikt Zinn | D10: Felix Hilgers | E10: Everyone else | F10: Paul Assenbaum | G10: Georgina Goldschmidt
A11: 9 | B11: =B10+7 -> 46008 | C11: Felix Hilgers | D11: Benedikt Zinn | E11: Everyone else | F11: Christoph Mantsch | G11: Georgina Goldschmidt
A12: 10 | B12: 44937 | C12: Benedikt Zinn | D12: Felix Hilgers | E12: Everyone else | F12: Christoph Mantsch | G12: Georgina Goldschmidt
A13: 11 | B13: =B12+7 -> 44944 | C13: Felix Hilgers | D13: Benedikt Zinn | E13: Everyone else | F13: Zohreh Asadi | G13: Georgina Goldschmidt
A14: 12 | B14: =B13+7 -> 44951 | C14: Benedikt Zinn | D14: Felix Hilgers | E14: Everyone else | F14: Zohreh Asadi | G14: Georgina Goldschmidt
A15: 13 | B15: =B14+7 -> 44958 | C15: Felix Hilgers | D15: Benedikt Zinn | E15: Everyone else | G15: Georgina Goldschmidt
A16: 14 | B16: =B15+7 -> 44965 | C16: Benedikt Zinn | D16: Felix Hilgers | E16: Everyone else | G16: Georgina Goldschmidt | H16: Demo day!
A17: 15 | B17: =B16+7 -> 44972 | C17: Felix Hilgers | D17: Benedikt Zinn | E17: Everyone else | G17: Georgina Goldschmidt | H17: Retrospective
A19: Product owners, software developers, and Scurm Master are set and ideally don't change over time; the critical part is the Release Manager role you need to define here

Sheet Team Contract
A1: Goals | B1: Development of a visual perception system for robots with an accuracy of >= 90%
A3: Meeting norms | B3: Zoom-Meetings in the meeting room of the university. Joining the meeting is mandatory, with exceptions (like sickness, etc.). As an exception, showing up to 10 minutes late is fine if the team is informed via discord. Happiness Index: has to be completed at the end of the meeting (amos happy). Stand-up-mails: containing -> things done, problems encountered, things up next. -> For SDs: min 2x per week -> For POs: min 1x per week
A5: Working norms | B5: Issues on Github in the “Feature board” project of the repository. Definition of Done: If specified in the issue that the feature has to be tested, tests have to be written for that feature, documented (in code or later in the wiki) Git-branches: The latest commit on the main-branch has to be tagged. Only 2 “in progress” tickets per person at one time.
A7: Coordination norms | B7: Developers can create issues but not put them onto the “Feature board”. If blocked by a different task, discuss it as soon as possible. Communication should happen via Discord & mail. Criticism should be constructive. Language should be respectful at all times, both verbal and written communication.
A9: Communication norms | B9: Developers can create issues but not put them onto the “Feature board”. If blocked by a different task, discuss it as soon as possible. Communication should happen via Discord & mail. Criticism should be constructive. Language should be respectful at all times, both verbal and written communication.
A11: Consideration norms
A13: Cont. improvement norms
A15: Rewards | B15: Online coffee or lunch meet at some point.
A17: Sanctions | B17: Document absence. Repeated absence is addressed with the missing person directly but will later be escalated to professors.
A19: Signatures
A21: Scrum Master | B21: Georgina Goldschmidt
A22: Product owner | B22: Felix Hilgers
A23: Product owner | B23: Benedikt Zinn
A24: Software developer | B24: Sarib Samdani
A25: Software developer | B25: Emil Badura
A26: Software developer | B26: Anuun Chinbat
A27: Software developer | B27: Paul Assenbaum
A28: Software developer | B28: Christoph Mantsch
A29: Software developer | B29: Zohreh Asadi

Sheet Product Goal
A1: Product Vision | B1: Project Mission
A3: The reason of existence of the envisioned product (beyond this project). | B3: The mission of this particular project (in the context of the product vision).

Sheet Product Glossary
A1: Term | B1: Definition

Sheet Sprint Goals
A1: Sprint # | B1: Sprint goal
A2: 1 | B2: Meeting with industry partner and getting things started (and the T-shirt of course)
A3: =A2+1 -> 2 | B3: Start work on individual components and research unclear topics
A4: =A3+1 -> 3 | B4: Combining components into a first working prototype
A5: =A4+1 -> 4 | B5: Refining prototype and splitting out components
A6: =A5+1 -> 5 | B6: Finishing the Implementation of the Initial Architecture
A7: =A6+1 -> 6
A8: =A7+1 -> 7
A9: =A8+1 -> 8
A10: =A9+1 -> 9
A11: =A10+1 -> 10
A12: =A11+1 -> 11
A13: =A12+1 -> 12
A14: =A13+1 -> 13
A15: =A14+1 -> 14
A16: =A15+1 -> 15

Sheet Velocity Tracking
A1: Sprint # | B1: Story Points Realized
A2: 1
A3: =A2+1 -> 2
A4: =A3+1 -> 3
A5: =A4+1 -> 4
A6: =A5+1 -> 5
A7: =A6+1 -> 6
A8: =A7+1 -> 7
A9: =A8+1 -> 8
A10: =A9+1 -> 9
A11: =A10+1 -> 10
A12: =A11+1 -> 11
A13: =A12+1 -> 12
A14: =A13+1 -> 13
... A16: =A15+1 -> 15
B18: PLEASE CREATE THE VELOCITY CHART ON A NEW TAB USING THE DATA FROM THIS TAB

Sheet Mid-Project Release plan
A1: Sprint | B1: Goal | C1: Feature Name | D1: Est. size | E1: Est. remaining | F1: Real size | G1: Real remaining
A3: Release
A5: Total | D5: =sum(D8:D13) -> 0 | E5: =D5 -> 0
A7: Sprints
E8: Estimated burn-down | G8: Real burn-down
A9: 1 | D9: =sum(D16:D21) -> 0 | E9: =$D$5 -> 0 | F9: =sum(F16:F21) -> 0 | G9: =$D$5 -> 0
A10: =A9+1 -> 2 | D10: =sum(D22:D27) -> 0 | E10: =E9-D9 -> 0 | F10: =sum(F22:F27) -> 0 | G10: =G9-F9 -> 0
A11: =A10+1 -> 3 | D11: =sum(D28:D33) -> 0 | E11: =E10-D10 -> 0 | F11: =sum(F28:F33) -> 0 | G11: =G10-F10 -> 0
A12: ... | E12: =E11-D11 -> 0 | G12: =G11-F11 -> 0
A14: Features
A16: =A9 -> 1 | B16: =B9
A22: =A10 -> 2 | B22: =B10
A28: =A11 -> 3 | B28: =B11
C33: PLEASE CREATE THE BURNDOWN CHART ON A NEW TAB USING THE DATA FROM THIS TAB

Sheet Final Project Release plan
A1: Sprint | B1: Goal | C1: Feature Name | D1: Est. size | E1: Est. remaining | F1: Real size | G1: Real remaining
A3: Release
A5: Total | D5: =sum(D8:D13) -> 0 | E5: =D5 -> 0
A7: Sprints
E8: Estimated burn-down | G8: Real burn-down
A9: 1 | D9: =sum(D16:D21) -> 0 | E9: =$D$5 -> 0 | F9: =sum(F16:F21) -> 0 | G9: =$D$5 -> 0
A10: =A9+1 -> 2 | D10: =sum(D22:D27) -> 0 | E10: =E9-D9 -> 0 | F10: =sum(F22:F27) -> 0 | G10: =G9-F9 -> 0
A11: =A10+1 -> 3 | D11: =sum(D28:D33) -> 0 | E11: =E10-D10 -> 0 | F11: =sum(F28:F33) -> 0 | G11: =G10-F10 -> 0
A12: ... | E12: =E11-D11 -> 0 | G12: =G11-F11 -> 0
A14: Features
A16: =A9 -> 1
A22: =A10 -> 2
A28: =A11 -> 3
C33: PLEASE CREATE THE BURNDOWN CHART ON A NEW TAB USING THE DATA FROM THIS TAB

Sheet Definition of Done
A1: # | B1: Feature Definition of Done | C1: Sprint Release Definition of Done | D1: Project Release Definition of Done

Sheet Documentation
A1: Type | B1: Link / reference

Sheet Bill of Materials
A1: # | B1: Context | C1: Name | D1: Version | E1: License | F1: Comment | G1: Status | H1: Change Info
A2: 1 | B2: Frontend (React UI) | C2: npm:react | D2: 18.3.1 | E2: MIT | F2: UI framework | G2: In Use
A3: 2 | B3: Frontend (React UI) | C3: npm:react-dom | D3: 18.3.1 | E3: MIT | F3: DOM renderer for React | G3: In Use
A4: 3 | B4: Frontend (React UI) | C4: npm:typescript | D4: 5.6.3 | E4: Apache-2.0 | F4: Type system for JavaScript | G4: In Use | H4: Version updated: 5.4.5 → 5.6.3
A5: 4 | B5: Frontend (React UI) | C5: npm:vite | D5: 6.0.3 | E5: MIT | F5: Build tool and dev server | G5: In Use | H5: Version updated: 5.2.0 → 6.0.3
A6: 5 | B6: Frontend (React UI) | C6: npm:websocket | D6: 1.0.35 | E6: MIT | F6: WebSocket client for metadata | G6: Planned
A7: 6 | B7: Frontend (React UI) | C7: npm:webrtc-adapter | D7: 9.1.2 | E7: BSD-3-Clause | F7: Cross-browser WebRTC compatibility | G7: Planned
A8: 7 | B8: Frontend (React UI) | C8: npm:axios | D8: 1.7.2 | E8: MIT | F8: HTTP client for REST API | G8: Planned
A9: 8 | B9: Frontend (React UI) | C9: npm: zustand | D9: 4.5.3 | E9: MIT | F9: State management | G9: Planned
A10: 9 | B10: Frontend (React UI) | C10: npm:three | D10: 0.169.0 | E10: MIT | F10: for 3D-visualization | G10: Planned (optional)
A11: 10 | B11: Frontend (React UI) | C11: npm:@types/react | D11: 18.3.12 | E11: MIT | F11: TypeScript definitions for React | G11: In Use | H11: New component
A12: 11 | B12: Frontend (React UI) | C12: npm:@types/react-dom | D12: 18.3.1 | E12: MIT | F12: TypeScript definitions for React DOM | G12: In Use | H12: New component
A13: 12 | B13: Frontend (React UI) | C13: npm:@vitejs/plugin-react | D13: 4.3.4 | E13: MIT | F13: Vite plugin for React support | G13: In Use | H13: New component
A14: 13 | B14: Frontend (React UI) | C14: npm:eslint | D14: 9.17.0 | E14: MIT | F14: Code linting | G14: In Use | H14: New component
A15: 14 | B15: Frontend (React UI) | C15: npm:prettier | D15: 3.4.2 | E15: MIT | F15: Code formatting | G15: In Use | H15: New component
A16: 15 | B16: Frontend (React UI) | C16: npm:vitest | D16: 2.1.5 | E16: MIT | F16: Unit testing framework | G16: In Use | H16: New component
A17: 16 | B17: Frontend (React UI) | C17: npm:@typescript-eslint/eslint-plugin | D17: 8.16.0 | E17: MIT | F17: ESLint rules for TypeScript | G17: In Use | H17: New component
A18: 17 | B18: Frontend (React UI) | C18: npm:@typescript-eslint/parser | D18: 8.16.0 | E18: MIT | F18: TypeScript parser for ESLint | G18: In Use | H18: New component
A19: 18 | B19: Backend (FastAPI API) | C19: pypi:uvicorn | D19: 0.38.0 | E19: BSD-3-Clause | F19: ASGI server for FastAPI | G19: In Use | H19: Version updated: 0.30.1 → 0.38.0
A20: 19 | B20: Backend (FastAPI API) | C20: pypi:fastapi | D20: 0.115.10 | E20: MIT | F20: Web framework for API | G20: In Use | H20: Version updated: 0.115.2 → 0.115.10
A21: 20 | B21: Backend (FastAPI API) | C21: pypi:websockets | D21: 13.1 | E21: BSD-3-Clause | F21: WebSocket server for real-time metadata | G21: Planned (optional)
A22: 21 | B22: Backend (FastAPI API) | C22: pypi:grpcio | D22: 1.66.1 | E22: Apache-2.0 | F22: gRPC for AI service communication | G22: Planned (optional)
A23: 22 | B23: Backend (FastAPI API) | C23: pypi:httpx | D23: 0.27.0 | E23: BSD-3-Clause | F23: Async HTTP client | G23: Planned
A24: 23 | B24: Backend (FastAPI API) | C24: pypi:pydantic | D24: 2.12.3 | E24: MIT | F24: Data validation for FastAPI | G24: In Use | H24: New component
A25: 24 | B25: Backend (FastAPI API) | C25: pypi:aiortc | D25: 1.14.0 | E25: BSD-3-Clause | F25: Python WebRTC implementation | G25: In Use | H25: New component
A26: 25 | B26: Backend (FastAPI API) | C26: pypi:av | D26: 16.0.1 | E26: BSD-2-Clause | F26: Audio/Video processing for aiortc | G26: In Use | H26: New component
A27: 26 | B27: Backend (FastAPI API) | C27: pypi:ruff | D27: 0.7.0 | E27: MIT | F27: Fast Python linter | G27: In Use | H27: New component
A28: 27 | B28: Backend (FastAPI API) | C28: pypi:pytest | D28: 8.3.3 | E28: MIT | F28: Testing framework | G28: In Use | H28: New component
A29: 28 | B29: Backend (FastAPI API) | C29: pypi:mypy | D29: 1.13.0 | E29: MIT | F29: Static type checker | G29: In Use | H29: New component
A30: 29 | B30: WebRTC Signaling | C30: go:pion/webrtc | D30: 3.2.35 | E30: MIT | F30: Go WebRTC library for signaling service | G30: Planned (optional)
A31: 30 | B31: WebRTC Signaling | C31: go:gorilla/websocket | D31: 1.5.2 | E31: BSD-2-Clause | F31: WebSocket library for Go | G31: Planned (optional)
A32: 31 | B32: Image Analysis (Python) | C32: pypi:opencv-python | D32: 4.9.0.80 | E32: Apache-2.0 | F32: Computer vision library | G32: In Use | H32: Version updated: 4.10.0.84 → 4.12.0.88
A33: 32 | B33: Image Analysis (Python) | C33: pypi:numpy | D33: 1.26.4 | E33: BSD-3-Clause | F33: Numerical operations | G33: In Use | H33: Version updated: 2.1.1 → 2.2.6
A34: 33 | B34: Image Analysis (Python) | C34: pypi:torch | D34: 2.3.1 | E34: BSD-3-Clause | F34: PyTorch ML framework | G34: Planned
A35: 34 | B35: Image Analysis (Python) | C35: pypi:torchvision | D35: 0.18.1 | E35: BSD-3-Clause | F35: Computer vision models for PyTorch | G35: Planned
A36: 35 | B36: Image Analysis (Python) | C36: pypi:midas | D36: 3.1 | E36: MIT | F36: for depth recognition | G36: Planned
A37: 36 | B37: Image Analysis (Python) | C37: pypi:ultralytics | D37: 8.2.14 | E37: APGL-3.0 | F37: for computer vision | G37: Planned
A38: 37 | B38: Infrastructure/Deployment | C38: docker:python | D38: 3.11-slim | E38: PSF | F38: Base container for Python services | G38: Planned
A39: 38 | B39: Infrastructure/Deployment | C39: docker:golang | D39: 20-alpine | E39: MIT | F39: Base container for Go service | G39: Planned
A40: 39 | B40: Infrastructure/Deployment | C40: docker:nvidia/cuda | D40: 12.4.1-base | E40: NVIDIA Software License | F40: GPU acceleration for AI inference | G40: Planned (optional)
...

Sheet Planning Poker
A1: ='Project Team'!A1 -> Last Name | B1: ='Project Team'!B1 -> First Name | C1: Value
A2: ='Project Team'!A2 -> Hilgers | B2: ='Project Team'!B2 -> Felix | E2: =average(C2:C9) -> #DIV/0! | F2: =if(stdev(C2:C7) > 0,"NOK", "OK") -> #DIV/0!
A4: ='Project Team'!A3 -> Samdani | B4: ='Project Team'!B3 -> Sarib
A5: ='Project Team'!A4 -> Chinbat | B5: ='Project Team'!B4 -> Anuun
A6: ='Project Team'!A7 -> Badura | B6: ='Project Team'!B7 -> Emil | E6: 0 | F6: No size
A7: ='Project Team'!A8 -> Assenbaum | B7: ='Project Team'!B8 -> Paul | E7: 1 | F7: Trivial size
A8: ='Project Team'!A9 -> Mantsch | B8: ='Project Team'!B9 -> Christoph | E8: 2 | F8: Small size
A9: Asadi | B9: Zohreh | E9: 3 | F9: Medium size
E10: 5 | F10: Large size
A11: ='Project Team'!A5 -> Goldschmidt | B11: ='Project Team'!B5 -> Georgina | E11: 8 | F11: Very large size
A12: ='Project Team'!A6 -> Zinn | B12: ='Project Team'!B6 -> Benedikt | E12: 13 | F12: Too large (size)
A14: How to play planning poker
A16: 1. Everyone type their number into their value field, don't hit return yet
A17: 2. Someone, perhaps a product owner, count down 3.. 2.. 1..
A18: 3. Then, everyone hit return to submit their value
G19: no cap yet
